Traceback (most recent call last):
  File "/home/madduru/.conda/envs/parsl_py36/bin/ipengine", line 6, in <module>
    from pkg_resources import load_entry_point
  File "<frozen importlib._bootstrap>", line 971, in _find_and_load
  File "<frozen importlib._bootstrap>", line 955, in _find_and_load_unlocked
  File "<frozen importlib._bootstrap>", line 665, in _load_unlocked
  File "<frozen importlib._bootstrap_external>", line 674, in exec_module
  File "<frozen importlib._bootstrap_external>", line 780, in get_code
  File "<frozen importlib._bootstrap_external>", line 833, in get_data
OSError: [Errno 14] Bad address
Traceback (most recent call last):
  File "/home/madduru/.conda/envs/parsl_py36/bin/ipengine", line 6, in <module>
    from pkg_resources import load_entry_point
  File "<frozen importlib._bootstrap>", line 971, in _find_and_load
  File "<frozen importlib._bootstrap>", line 955, in _find_and_load_unlocked
  File "<frozen importlib._bootstrap>", line 665, in _load_unlocked
  File "<frozen importlib._bootstrap_external>", line 674, in exec_module
  File "<frozen importlib._bootstrap_external>", line 780, in get_code
  File "<frozen importlib._bootstrap_external>", line 833, in get_data
OSError: [Errno 14] Bad address
Traceback (most recent call last):
  File "/home/madduru/.conda/envs/parsl_py36/bin/ipengine", line 6, in <module>
    from pkg_resources import load_entry_point
  File "<frozen importlib._bootstrap>", line 971, in _find_and_load
  File "<frozen importlib._bootstrap>", line 955, in _find_and_load_unlocked
  File "<frozen importlib._bootstrap>", line 665, in _load_unlocked
  File "<frozen importlib._bootstrap_external>", line 674, in exec_module
  File "<frozen importlib._bootstrap_external>", line 780, in get_code
  File "<frozen importlib._bootstrap_external>", line 833, in get_data
OSError: [Errno 14] Bad address
Traceback (most recent call last):
  File "/home/madduru/.conda/envs/parsl_py36/bin/ipengine", line 6, in <module>
    from pkg_resources import load_entry_point
  File "<frozen importlib._bootstrap>", line 971, in _find_and_load
  File "<frozen importlib._bootstrap>", line 955, in _find_and_load_unlocked
  File "<frozen importlib._bootstrap>", line 665, in _load_unlocked
  File "<frozen importlib._bootstrap_external>", line 674, in exec_module
  File "<frozen importlib._bootstrap_external>", line 780, in get_code
  File "<frozen importlib._bootstrap_external>", line 833, in get_data
OSError: [Errno 14] Bad address
Traceback (most recent call last):
  File "/home/madduru/.conda/envs/parsl_py36/bin/ipengine", line 6, in <module>
    from pkg_resources import load_entry_point
  File "<frozen importlib._bootstrap>", line 971, in _find_and_load
  File "<frozen importlib._bootstrap>", line 955, in _find_and_load_unlocked
  File "<frozen importlib._bootstrap>", line 665, in _load_unlocked
  File "<frozen importlib._bootstrap_external>", line 674, in exec_module
  File "<frozen importlib._bootstrap_external>", line 780, in get_code
  File "<frozen importlib._bootstrap_external>", line 833, in get_data
OSError: [Errno 14] Bad address
Traceback (most recent call last):
  File "/home/madduru/.conda/envs/parsl_py36/bin/ipengine", line 6, in <module>
    from pkg_resources import load_entry_point
  File "<frozen importlib._bootstrap>", line 971, in _find_and_load
  File "<frozen importlib._bootstrap>", line 955, in _find_and_load_unlocked
  File "<frozen importlib._bootstrap>", line 665, in _load_unlocked
  File "<frozen importlib._bootstrap_external>", line 674, in exec_module
  File "<frozen importlib._bootstrap_external>", line 780, in get_code
  File "<frozen importlib._bootstrap_external>", line 833, in get_data
OSError: [Errno 14] Bad address
Traceback (most recent call last):
  File "/home/madduru/.conda/envs/parsl_py36/bin/ipengine", line 6, in <module>
    from pkg_resources import load_entry_point
  File "<frozen importlib._bootstrap>", line 971, in _find_and_load
  File "<frozen importlib._bootstrap>", line 955, in _find_and_load_unlocked
  File "<frozen importlib._bootstrap>", line 665, in _load_unlocked
  File "<frozen importlib._bootstrap_external>", line 674, in exec_module
  File "<frozen importlib._bootstrap_external>", line 780, in get_code
  File "<frozen importlib._bootstrap_external>", line 833, in get_data
OSError: [Errno 14] Bad address
Traceback (most recent call last):
  File "/home/madduru/.conda/envs/parsl_py36/bin/ipengine", line 6, in <module>
    from pkg_resources import load_entry_point
  File "<frozen importlib._bootstrap>", line 971, in _find_and_load
  File "<frozen importlib._bootstrap>", line 955, in _find_and_load_unlocked
  File "<frozen importlib._bootstrap>", line 665, in _load_unlocked
  File "<frozen importlib._bootstrap_external>", line 674, in exec_module
  File "<frozen importlib._bootstrap_external>", line 780, in get_code
  File "<frozen importlib._bootstrap_external>", line 833, in get_data
OSError: [Errno 14] Bad address
Traceback (most recent call last):
  File "/home/madduru/.conda/envs/parsl_py36/bin/ipengine", line 6, in <module>
    from pkg_resources import load_entry_point
  File "<frozen importlib._bootstrap>", line 971, in _find_and_load
  File "<frozen importlib._bootstrap>", line 955, in _find_and_load_unlocked
  File "<frozen importlib._bootstrap>", line 665, in _load_unlocked
  File "<frozen importlib._bootstrap_external>", line 674, in exec_module
  File "<frozen importlib._bootstrap_external>", line 780, in get_code
  File "<frozen importlib._bootstrap_external>", line 833, in get_data
OSError: [Errno 14] Bad address
Traceback (most recent call last):
  File "/home/madduru/.conda/envs/parsl_py36/bin/ipengine", line 6, in <module>
    from pkg_resources import load_entry_point
  File "<frozen importlib._bootstrap>", line 971, in _find_and_load
  File "<frozen importlib._bootstrap>", line 955, in _find_and_load_unlocked
  File "<frozen importlib._bootstrap>", line 665, in _load_unlocked
  File "<frozen importlib._bootstrap_external>", line 674, in exec_module
  File "<frozen importlib._bootstrap_external>", line 780, in get_code
  File "<frozen importlib._bootstrap_external>", line 833, in get_data
OSError: [Errno 14] Bad address
Traceback (most recent call last):
  File "/home/madduru/.conda/envs/parsl_py36/bin/ipengine", line 6, in <module>
    from pkg_resources import load_entry_point
  File "<frozen importlib._bootstrap>", line 971, in _find_and_load
  File "<frozen importlib._bootstrap>", line 955, in _find_and_load_unlocked
  File "<frozen importlib._bootstrap>", line 665, in _load_unlocked
  File "<frozen importlib._bootstrap_external>", line 674, in exec_module
  File "<frozen importlib._bootstrap_external>", line 780, in get_code
  File "<frozen importlib._bootstrap_external>", line 833, in get_data
OSError: [Errno 14] Bad address
Traceback (most recent call last):
  File "/home/madduru/.conda/envs/parsl_py36/bin/ipengine", line 6, in <module>
    from pkg_resources import load_entry_point
  File "<frozen importlib._bootstrap>", line 971, in _find_and_load
  File "<frozen importlib._bootstrap>", line 955, in _find_and_load_unlocked
  File "<frozen importlib._bootstrap>", line 665, in _load_unlocked
  File "<frozen importlib._bootstrap_external>", line 674, in exec_module
  File "<frozen importlib._bootstrap_external>", line 780, in get_code
  File "<frozen importlib._bootstrap_external>", line 833, in get_data
OSError: [Errno 14] Bad address
Traceback (most recent call last):
  File "/home/madduru/.conda/envs/parsl_py36/bin/ipengine", line 6, in <module>
    from pkg_resources import load_entry_point
  File "<frozen importlib._bootstrap>", line 971, in _find_and_load
  File "<frozen importlib._bootstrap>", line 955, in _find_and_load_unlocked
  File "<frozen importlib._bootstrap>", line 665, in _load_unlocked
  File "<frozen importlib._bootstrap_external>", line 674, in exec_module
  File "<frozen importlib._bootstrap_external>", line 780, in get_code
  File "<frozen importlib._bootstrap_external>", line 833, in get_data
OSError: [Errno 14] Bad address
Traceback (most recent call last):
  File "/home/madduru/.conda/envs/parsl_py36/bin/ipengine", line 6, in <module>
    from pkg_resources import load_entry_point
  File "<frozen importlib._bootstrap>", line 971, in _find_and_load
  File "<frozen importlib._bootstrap>", line 955, in _find_and_load_unlocked
  File "<frozen importlib._bootstrap>", line 665, in _load_unlocked
  File "<frozen importlib._bootstrap_external>", line 674, in exec_module
  File "<frozen importlib._bootstrap_external>", line 780, in get_code
  File "<frozen importlib._bootstrap_external>", line 833, in get_data
OSError: [Errno 14] Bad address
Traceback (most recent call last):
  File "/home/madduru/.conda/envs/parsl_py36/bin/ipengine", line 6, in <module>
    from pkg_resources import load_entry_point
  File "<frozen importlib._bootstrap>", line 971, in _find_and_load
  File "<frozen importlib._bootstrap>", line 955, in _find_and_load_unlocked
  File "<frozen importlib._bootstrap>", line 665, in _load_unlocked
  File "<frozen importlib._bootstrap_external>", line 674, in exec_module
  File "<frozen importlib._bootstrap_external>", line 780, in get_code
  File "<frozen importlib._bootstrap_external>", line 833, in get_data
OSError: [Errno 14] Bad address
Traceback (most recent call last):
  File "/home/madduru/.conda/envs/parsl_py36/bin/ipengine", line 6, in <module>
    from pkg_resources import load_entry_point
  File "<frozen importlib._bootstrap>", line 971, in _find_and_load
  File "<frozen importlib._bootstrap>", line 955, in _find_and_load_unlocked
  File "<frozen importlib._bootstrap>", line 665, in _load_unlocked
  File "<frozen importlib._bootstrap_external>", line 674, in exec_module
  File "<frozen importlib._bootstrap_external>", line 780, in get_code
  File "<frozen importlib._bootstrap_external>", line 833, in get_data
OSError: [Errno 14] Bad address
Traceback (most recent call last):
  File "/home/madduru/.conda/envs/parsl_py36/bin/ipengine", line 6, in <module>
    from pkg_resources import load_entry_point
  File "<frozen importlib._bootstrap>", line 971, in _find_and_load
  File "<frozen importlib._bootstrap>", line 955, in _find_and_load_unlocked
  File "<frozen importlib._bootstrap>", line 665, in _load_unlocked
  File "<frozen importlib._bootstrap_external>", line 674, in exec_module
  File "<frozen importlib._bootstrap_external>", line 780, in get_code
  File "<frozen importlib._bootstrap_external>", line 833, in get_data
OSError: [Errno 14] Bad address
Traceback (most recent call last):
  File "/home/madduru/.conda/envs/parsl_py36/bin/ipengine", line 6, in <module>
    from pkg_resources import load_entry_point
  File "<frozen importlib._bootstrap>", line 971, in _find_and_load
  File "<frozen importlib._bootstrap>", line 955, in _find_and_load_unlocked
  File "<frozen importlib._bootstrap>", line 665, in _load_unlocked
  File "<frozen importlib._bootstrap_external>", line 674, in exec_module
  File "<frozen importlib._bootstrap_external>", line 780, in get_code
  File "<frozen importlib._bootstrap_external>", line 833, in get_data
OSError: [Errno 14] Bad address
Traceback (most recent call last):
  File "/home/madduru/.conda/envs/parsl_py36/bin/ipengine", line 6, in <module>
    from pkg_resources import load_entry_point
  File "<frozen importlib._bootstrap>", line 971, in _find_and_load
  File "<frozen importlib._bootstrap>", line 955, in _find_and_load_unlocked
  File "<frozen importlib._bootstrap>", line 665, in _load_unlocked
  File "<frozen importlib._bootstrap_external>", line 674, in exec_module
  File "<frozen importlib._bootstrap_external>", line 780, in get_code
  File "<frozen importlib._bootstrap_external>", line 833, in get_data
OSError: [Errno 14] Bad address
